<?xml version="1.0" ?>
<!-- =================================================================================== -->
<!-- |    This document was autogenerated by xacro from gen3_robotiq_2f_85.xacro       | -->
<!-- |    EDITING THIS FILE BY HAND IS NOT RECOMMENDED                                 | -->
<!-- =================================================================================== -->
<robot name="kinova" xmlns:xacro="http://www.ros.org/wiki/xacro">
  <!-- Run the macros -->
  <link name="kinova_link0">
    <inertial>
      <origin rpy="0 0 0" xyz="0 0 0"/>
      <mass value="1.697"/>
      <inertia ixx="0.004622" ixy="9E-06" ixz="6E-05" iyy="0.004495" iyz="9E-06" izz="0.002079"/>
    </inertial>
    <visual>
      <origin rpy="0 0 0" xyz="0 0 0"/>
      <geometry>
        <mesh filename="package://meshes/visual/base_link.STL"/>
      </geometry>
      <material name="kinova_blue"/>
    </visual>
    <collision>
      <origin rpy="0 0 0" xyz="0 0 0"/>
      <geometry>
        <mesh filename="package://meshes/collision/base_link.STL"/>
      </geometry>
    </collision>
  </link>

  <link name="kinova_link1">
    <inertial>
      <origin rpy="0 0 0" xyz="0 0 0"/>
      <mass value="1.3773"/>
      <inertia ixx="0.00457" ixy="1E-06" ixz="2E-06" iyy="0.004831" iyz="0.000448" izz="0.001409"/>
    </inertial>
    <visual>
      <origin rpy="0 0 0" xyz="0 0 0"/>
      <geometry>
        <mesh filename="package://meshes/visual/shoulder_link.STL"/>
      </geometry>
      <material name="kinova_white"/>
    </visual>
    <collision>
      <origin rpy="0 0 0" xyz="0 0 0"/>
      <geometry>
        <mesh filename="package://meshes/collision/shoulder_link.STL"/>
      </geometry>
    </collision>
  </link>

  <joint name="joint_1" type="continuous">
    <safety_controller k_position="100.0" k_velocity="40.0" />
    <origin rpy="3.1416 0 0" xyz="0 0 0.15643"/>
    <parent link="kinova_link0"/>
    <child link="kinova_link1"/>
    <axis xyz="0 0 1"/>
    <limit effort="87" velocity="2.1750"/>
    <dynamics damping="0.5"/>
  </joint>

  <link name="kinova_link2">
    <inertial>
      <origin rpy="0 0 0" xyz="0 0 0"/>
      <mass value="1.1636"/>
      <inertia ixx="0.011088" ixy="5E-06" ixz="0" iyy="0.001072" iyz="-0.000691" izz="0.011255"/>
    </inertial>
    <visual>
      <origin rpy="0 0 0" xyz="0 0 0"/>
      <geometry>
        <mesh filename="package://meshes/visual/half_arm_1_link.STL"/>
      </geometry>
      <material name="kinova_white"/>
    </visual>
    <collision>
      <origin rpy="0 0 0" xyz="0 0 0"/>
      <geometry>
        <mesh filename="package://meshes/collision/half_arm_1_link.STL"/>
      </geometry>
    </collision>
  </link>

  <joint name="joint_2" type="revolute">
    <origin rpy="1.5708 0 0" xyz="0 0.005375 -0.12838"/>
    <parent link="kinova_link1"/>
    <child link="kinova_link2"/>
    <axis xyz="0 0 1"/>
    <limit effort="87" lower="-2.24" upper="2.24" velocity="1.3963"/>
    <dynamics damping="0.5"/>
  </joint>

  <link name="kinova_link3">
    <inertial>
      <origin rpy="0 0 0" xyz="0 0 0"/>
      <mass value="1.1636"/>
      <inertia ixx="0.010932" ixy="0" ixz="-7E-06" iyy="0.011127" iyz="0.000606" izz="0.001043"/>
    </inertial>
    <visual>
      <origin rpy="0 0 0" xyz="0 0 0"/>
      <geometry>
        <mesh filename="package://meshes/visual/half_arm_2_link.STL"/>
      </geometry>
      <material name="kinova_white"/>
    </visual>
    <collision>
      <origin rpy="0 0 0" xyz="0 0 0"/>
      <geometry>
        <mesh filename="package://meshes/collision/half_arm_2_link.STL"/>
      </geometry>
    </collision>
  </link>

  <joint name="joint_3" type="continuous">
    <origin rpy="-1.5708 0 0" xyz="0 -0.21038 -0.006375"/>
    <parent link="kinova_link2"/>
    <child link="kinova_link3"/>
    <axis xyz="0 0 1"/>
    <limit effort="87" velocity="1.3963"/>
    <dynamics damping="0.5"/>
  </joint>

  <link name="kinova_link4">
    <inertial>
      <origin rpy="0 0 0" xyz="0 0 0"/>
      <mass value="0.9302"/>
      <inertia ixx="0.008147" ixy="-1E-06" ixz="0" iyy="0.000631" iyz="-0.0005" izz="0.008316"/>
    </inertial>
    <visual>
      <origin rpy="0 0 0" xyz="0 0 0"/>
      <geometry>
        <mesh filename="package://meshes/visual/forearm_link.STL"/>
      </geometry>
      <material name="kinova_white"/>
    </visual>
    <collision>
      <origin rpy="0 0 0" xyz="0 0 0"/>
      <geometry>
        <mesh filename="package://meshes/collision/forearm_link.STL"/>
      </geometry>
    </collision>
  </link>

  <joint name="joint_4" type="revolute">
    <origin rpy="1.5708 0 0" xyz="0 0.006375 -0.21038"/>
    <parent link="kinova_link3"/>
    <child link="kinova_link4"/>
    <axis xyz="0 0 1"/>
    <limit effort="87" lower="-2.57" upper="2.57" velocity="1.3963"/>
    <dynamics damping="0.5"/>
  </joint>

  <link name="kinova_link5">
    <inertial>
      <origin rpy="0 0 0" xyz="0 0 0"/>
      <mass value="0.6781"/>
      <inertia ixx="0.001596" ixy="0" ixz="0" iyy="0.001607" iyz="0.000256" izz="0.000399"/>
    </inertial>
    <visual>
      <origin rpy="0 0 0" xyz="0 0 0"/>
      <geometry>
        <mesh filename="package://meshes/visual/spherical_wrist_1_link.STL"/>
      </geometry>
      <material name="kinova_white"/>
    </visual>
    <collision>
      <origin rpy="0 0 0" xyz="0 0 0"/>
      <geometry>
        <mesh filename="package://meshes/collision/spherical_wrist_1_link.STL"/>
      </geometry>
    </collision>
  </link>

  <joint name="joint_5" type="continuous">
    <origin rpy="-1.5708 0 0" xyz="0 -0.20843 -0.006375"/>
    <parent link="kinova_link4"/>
    <child link="kinova_link5"/>
    <axis xyz="0 0 1"/>
    <limit effort="12" velocity="1.2218"/>
    <dynamics damping="0.5"/>
  </joint>

  <link name="kinova_link6">
    <inertial>
      <origin rpy="0 0 0" xyz="0 0 0"/>
      <mass value="0.6781"/>
      <inertia ixx="0.001641" ixy="0" ixz="0" iyy="0.00041" iyz="-0.000278" izz="0.001641"/>
    </inertial>
    <visual>
      <origin rpy="0 0 0" xyz="0 0 0"/>
      <geometry>
        <mesh filename="package://meshes/visual/spherical_wrist_2_link.STL"/>
      </geometry>
      <material name="kinova_white"/>
    </visual>
    <collision>
      <origin rpy="0 0 0" xyz="0 0 0"/>
      <geometry>
        <mesh filename="package://meshes/collision/spherical_wrist_2_link.STL"/>
      </geometry>
    </collision>
  </link>

  <joint name="joint_6" type="revolute">
    <origin rpy="1.5708 0 0" xyz="0 0.00017505 -0.10593"/>
    <parent link="kinova_link5"/>
    <child link="kinova_link6"/>
    <axis xyz="0 0 1"/>
    <limit effort="12" lower="-2.09" upper="2.09" velocity="1.2218"/>
    <dynamics damping="0.5"/>
  </joint>

  <link name="kinova_link7">
    <inertial>
      <origin rpy="0 0 0" xyz="0 0 0"/>
      <mass value="0.5"/>
      <inertia ixx="0.000587" ixy="3E-06" ixz="3E-06" iyy="0.000369" iyz="-0.000118" izz="0.000609"/>
    </inertial>
    <visual>
      <origin rpy="0 0 0" xyz="0 0 0"/>
      <geometry>
        <mesh filename="package://meshes/visual/bracelet_with_vision_link.STL"/>
      </geometry>
      <material name="kinova_white"/>
    </visual>0.00017505
    <collision>
      <origin rpy="0 0 0" xyz="0 0 0"/>
      <geometry>
        <mesh filename="package://meshes/collision/bracelet_with_vision_link.STL"/>
      </geometry>
    </collision>
  </link>

  <joint name="joint_7" type="continuous">
    <origin rpy="-1.5708 0 0" xyz="0 -0.10593 -0.00017505"/>
    <parent link="kinova_link6"/>
    <child link="kinova_link7"/>
    <axis xyz="0 0 1"/>
    <limit effort="12" velocity="1.2218"/>
    <dynamics damping="0.5"/>
  </joint>

  <joint name="gripper_base_joint" type="fixed">
    <parent link="kinova_link7"/>
    <child link="robotiq_85_base_link"/>
    <origin rpy="3.14159265358979 0 0" xyz="0 0 -0.065529"/>
  </joint>

  <link
    name="robotiq_85_base_link">
    <inertial>
      <origin
        rpy="0 0 0" xyz="0 0 0"/>
      <mass
        value="0.30915" />
      <inertia
        ixx="0.00028972"
        ixy="-5.7879E-10"
        ixz="-1.8543E-06"
        iyy="0.00030737"
        iyz="1.682E-12"
        izz="0.00019914" />
    </inertial>
    <visual>
      <origin
        xyz="0 0 0"
        rpy="0 0 0" />
      <geometry>
        <mesh
          filename="package://meshes/visual/robotiq_85_base_link_fine.STL" />
      </geometry>
      <material name="gripper_black"/>
    </visual>
    <collision>
      <origin rpy="0 0 0" xyz="0 0 0"/>
      <geometry>
        <mesh filename="package://meshes/visual/robotiq_85_base_link_fine.STL"/>
      </geometry>
    </collision>
  </link>

  <link
    name="left_outer_knuckle">
    <inertial>
      <origin
        rpy="0 0 0" xyz="0 0 0"/>
      <mass
        value="0.00684838849434396" />
      <inertia
        ixx="2.66832029033166E-07"
        ixy="1.66142314639824E-15"
        ixz="1.45945633322873E-07"
        iyy="1.3889233257419E-06"
        iyz="2.82951161241588E-15"
        izz="1.26603336914415E-06" />
    </inertial>
    <visual>
      <origin
        xyz="0 0 0"
        rpy="0 0 0" />
      <geometry>
        <mesh
          filename="package://meshes/visual/outer_knuckle_fine.STL" />
      </geometry>
      <material name="gripper_lightGrey"/>
    </visual>
  </link>
  <joint
    name="finger_joint"
    type="revolute">
    <origin
      xyz="0.0306011444260539 0 0.0627920162695395"
      rpy="0 0 0" />
    <parent
      link="robotiq_85_base_link" />
    <child
      link="left_outer_knuckle" />
    <axis
      xyz="0 -1 0" />
    <limit
	    effort="20"  
      lower="-0.35"
      upper="0.673"
      velocity="2.0"/>
  </joint>
  <link
    name="left_outer_finger">
    <inertial>
      <origin
        rpy="0 0 0" xyz="0 0 0"/>
      <mass
        value="0.0273093985570947" />
      <inertia
        ixx="8.51629628283022E-06"
        ixy="2.58174336207405E-19"
        ixz="3.83829504344079E-07"
        iyy="6.9133328065108E-06"
        iyz="-7.58589926143789E-19"
        izz="2.25006832221981E-06" />
    </inertial>
    <visual>
      <origin
        xyz="0 0 0"
        rpy="0 0 0" />
      <geometry>
        <mesh
          filename="package://meshes/visual/outer_finger_fine.STL" />
      </geometry>
      <material name="gripper_black"/>
    </visual>
  </link>
  <joint
    name="left_outer_finger_joint"
    type="fixed">
    <origin
      xyz="0.0316910442266543 0 -0.00193396375724605"
      rpy="0 0 0" />
    <parent
      link="left_outer_knuckle" />
    <child
      link="left_outer_finger" />
    <axis
      xyz="0 -1 0" />
  </joint>
  <link
    name="left_inner_knuckle">
    <inertial>
      <origin
        rpy="0 0 0" xyz="0 0 0"/>
      <mass
        value="0.0110930853895903" />
      <inertia
        ixx="4.23392770691541E-06"
        ixy="5.748978936968E-15"
        ixz="1.78855677119788E-06"
        iyy="3.96548790524392E-06"
        iyz="1.05464666369669E-14"
        izz="3.24068002883007E-06" />
    </inertial>
    <visual>
      <origin
        xyz="0 0 0"
        rpy="0 0 0" />
      <geometry>
        <mesh
          filename="package://meshes/visual/inner_knuckle_fine.STL" />
      </geometry>
      <material name="gripper_black"/>
    </visual>
  </link>
  <joint
    name="left_inner_knuckle_joint"
    type="revolute">
    <origin
      xyz="0.0127000000001501 0 0.0693074999999639"
      rpy="0 0 0" />
    <parent
      link="robotiq_85_base_link" />
    <child
      link="left_inner_knuckle" />
    <axis
      xyz="0 -1 0" />
    <limit
      effort="20"
      velocity="2.0"/>
    <mimic 
      joint="finger_joint"
      multiplier="1"
      offset="0" />
  </joint>

  <link
    name="left_inner_finger">
    <contact>
      <friction_anchor/>
      <stiffness value="30000.0"/>
      <damping value="1000.0"/>
      <spinning_friction value="0.1"/>
      <lateral_friction value="1.0"/>
    </contact>
    <inertial>
      <origin
        rpy="0 0 0" xyz="0 0 0"/>
      <mass
        value="0.00724255346165745" />
      <inertia
        ixx="1.47824274053603E-06"
        ixy="-3.94884463570303E-19"
        ixz="-3.45268847648622E-07"
        iyy="1.70064480838395E-06"
        iyz="3.5059838910097E-19"
        izz="4.77151336838364E-07" />
    </inertial>
    <visual>
      <origin
        xyz="0 0 0"
        rpy="1.57 0 0" />
      <geometry>
        <mesh
          filename="package://meshes/visual/inner_finger_pipe_fine.obj" />
      </geometry>
      <material name="gripper_lightGrey"/>
    </visual>
    <collision>
      <origin
        xyz="0.0014 0 0"
        rpy="0 0 0" />
      <geometry>
        <mesh
          filename="package://meshes/visual/inner_finger_fine.STL" />
      </geometry>
    </collision>
  </link>
  <joint
    name="left_inner_finger_joint"
    type="prismatic">
    <origin
      xyz="0.05 0 0.12"
      rpy="0 0 0" />
    <parent
      link="robotiq_85_base_link" />
    <child
      link="left_inner_finger" />
    <axis
      xyz="1 0 0" />
    <limit
      effort="20"
      velocity="2.0"/>
  </joint>

  <link
    name="right_inner_knuckle">
    <inertial>
      <origin
        rpy="0 0 0" xyz="0 0 0"/>
      <mass
        value="0.0110930853895903" />
      <inertia
        ixx="4.27134775939882E-06"
        ixy="-8.53568456728898E-15"
        ixz="1.77774229944246E-06"
        iyy="3.96548790524392E-06"
        iyz="-8.45108024914164E-15"
        izz="3.20325997634666E-06" />
    </inertial>
    <visual>
      <origin
        xyz="0 0 0"
        rpy="0 0 0" />
      <geometry>
        <mesh
          filename="package://meshes/visual/inner_knuckle_fine.STL" />
      </geometry>
      <material name="gripper_black"/>
    </visual>
  </link>
  <joint
    name="right_inner_knuckle_joint"
    type="revolute">
    <origin
      xyz="-0.0126999999998499 0 0.0693075000000361"
      rpy="0 0 3.14159265358979" />
    <parent
      link="robotiq_85_base_link" />
    <child
      link="right_inner_knuckle" />
    <axis
      xyz="0 1 0" />
    <limit
      effort="20"
      velocity="2.0"/>
    <mimic 
      joint="finger_joint"
      multiplier="-1"
      offset="0" />
  </joint>
  <link
    name="right_inner_finger">
    <contact>
      <friction_anchor/>
      <stiffness value="30000.0"/>
      <damping value="1000.0"/>
      <spinning_friction value="0.1"/>
      <lateral_friction value="1.0"/>
    </contact>
    <inertial>
      <origin
        rpy="0 0 0" xyz="0 0 0"/>
      <mass
        value="0.00724255346165744" />
      <inertia
        ixx="1.47824283625957E-06"
        ixy="-3.95952064019123E-19"
        ixz="-3.45268708875543E-07"
        iyy="1.70064480838394E-06"
        iyz="3.55286507960029E-19"
        izz="4.77151241114822E-07" />
    </inertial>
    <visual>
      <origin
        xyz="0 0 0"
        rpy="1.57 0 0" />
      <geometry>
        <mesh
          filename="package://meshes/visual/inner_finger_fine.obj" />
      </geometry>
      <material name="gripper_lightGrey"/>
    </visual>
    <collision>
      <origin
        xyz="0.0014 0 0"
        rpy="0 0 0" />
      <geometry>
        <mesh
          filename="package://meshes/visual/inner_finger_fine.STL" />
      </geometry>
    </collision>
  </link>
  <joint
    name="right_inner_finger_joint"
    type="prismatic">
    <origin
      xyz="-0.05 0 0.12"
      rpy="0 0 3.14" />
    <parent
      link="robotiq_85_base_link" />
    <child
      link="right_inner_finger" />
    <axis
      xyz="1 0 0" />
    <limit
      effort="20"
      velocity="2.0"/>
    <mimic 
      joint="left_inner_finger_joint"
      multiplier="1"
      offset="0" />
  </joint>
  <link
    name="right_outer_knuckle">
    <inertial>
      <origin
        rpy="0 0 0" xyz="0 0 0"/>
      <mass
        value="0.00684838849401352" />
      <inertia
        ixx="2.70004361573169E-07"
        ixy="1.59579467624491E-15"
        ixz="1.56396493788199E-07"
        iyy="1.38892332558312E-06"
        iyz="2.82357800318817E-15"
        izz="1.26286103637978E-06" />
    </inertial>
    <visual>
      <origin
        xyz="0 0 0"
        rpy="0 0 0" />
      <geometry>
        <mesh
          filename="package://meshes/visual/outer_knuckle_fine.STL" />
      </geometry>
      <material name="gripper_lightGrey"/>
    </visual>
  </link>
  <joint
    name="right_outer_knuckle_joint"
    type="revolute">
    <origin
      xyz="-0.0306011444258893 0 0.0627920162695395"
      rpy="0 0 3.14159265358979" />
    <parent
      link="robotiq_85_base_link" />
    <child
      link="right_outer_knuckle" />
    <axis
      xyz="0 1 0" />
    <limit
      effort="20"
      velocity="2.0"/>
    <mimic 
      joint="finger_joint"
      multiplier="-1"
      offset="0" />
  </joint>
  <link
    name="right_outer_finger">
    <inertial>
      <origin
        rpy="0 0 0" xyz="0 0 0"/>
      <mass
        value="0.0273093985570947" />
      <inertia
        ixx="8.52366028592721E-06"
        ixy="3.41683380899422E-19"
        ixz="3.18003675694284E-07"
        iyy="6.91333280651081E-06"
        iyz="7.37726682706417E-19"
        izz="2.24270431912283E-06" />
    </inertial>
    <visual>
      <origin
        xyz="0 0 0"
        rpy="0 0 0" />
      <geometry>
        <mesh
          filename="package://meshes/visual/outer_finger_fine.STL" />
      </geometry>
      <material name="gripper_black"/>
    </visual>
  </link>
  <joint
    name="right_outer_finger_joint"
    type="fixed">
    <origin
      xyz="0.0317095909367246 0 -0.0016013564954687"
      rpy="0 0 0" />
    <parent
      link="right_outer_knuckle" />
    <child
      link="right_outer_finger" />
    <axis
      xyz="0 1 0" />
  </joint>

  <collision_filter name="collision_filter_name">
        <!-- Exclude collisions between link1 and link2 -->
        <exclude link1="robotiq_85_base_link" link2="left_outer_knuckle"/>
        <exclude link1="left_outer_knuckle" link2="left_outer_finger"/>
        <exclude link1="robotiq_85_base_link" link2="left_inner_knuckle"/>
        <exclude link1="left_inner_knuckle" link2="left_inner_finger"/>
        <exclude link1="left_inner_finger" link2="left_outer_finger"/>
        <exclude link1="robotiq_85_base_link" link2="left_outer_knuckle"/>
        <exclude link1="right_outer_knuckle" link2="right_outer_finger"/>
        <exclude link1="robotiq_85_base_link" link2="right_inner_knuckle"/>
        <exclude link1="right_inner_knuckle" link2="right_inner_finger"/>
        <exclude link1="right_inner_finger" link2="right_outer_finger"/>
    </collision_filter>

  <!-- This line was removed by Kinova because we replaced the transmission file with our own 
    <xacro:include filename="$(find robotiq_2f_85_gripper_visualization)/urdf/robotiq_arg2f_transmission.xacro" /> -->
  <!-- Tool frame used by the arm -->


  <material name="kinova_white">
    <color rgba="1.0 1.0 1.0 1.0"/>
  </material>
  <material name="kinova_grey">
    <color rgba="0.7 0.7 0.7 1.0"/>
  </material>
  <material name="kinova_blue">
    <color rgba="0.2 0.2 0.8 1.0"/>
  </material>


  <material name="gripper_black">
    <color rgba="0.1 0.1 0.1 1.0"/>
  </material>
  <material name="gripper_lightGrey">
    <color rgba="0.9 0.9 0.9 1.0"/>
  </material>
  <material name="gripper_grey">
    <color rgba="0.5 0.5 0.5 1.0"/>
  </material>
  <material name="gripper_red">
    <color rgba="0.9 0 0 1.0"/>
  </material>



</robot>
